Workbook

Sheet Master - Brand Overview
A2: Brand Name | B2: Website URL | C2: Category | D2: Category | E2: Total Active Ads | F2: Video Ads Count | G2: Image Ads Count | H2: Image Ad Ratio | I2: Pass 35% Filter | J2: Landing pages | K2: Số lượng ads/prelanding chạy ads | L2: Số lượng page Blog | M2: Traffic | N2: %Meta | O2: AOV | P2: % Prelander | Q2: Est Revenue | R2: Ad Efficiency | S2: Checkout champ | T2: Note
A3: GNC | B3: gnc.com | C3: General Supplements | D3: US | E3: 2300 | F3: 730 | G3: 1500 | H3: =G3/E3 -> 0.65217391 | I3: =IF(AND(H3>=30%, E3>100), "Pass", "Fail") -> Pass | J3: View details | K3: 0 | L3: 0 | M3: =2.846*1000000 -> 2846000 | N3: 0.502 | O3: 68 | P3: =K3/G3 -> 0 | Q3: =O3*2.5%*(M3*N3) -> 2428776.4 | R3: =Q3/E3 -> 1055.9897 | S3: FALSE
A4: Tryrosabella | B4: get.tryrosabella.com | C4: Women's Wellness | D4: US | E4: 5500 | F4: 2400 | G4: 3100 | H4: =G4/E4 -> 0.56363636 | I4: =IF(AND(H4>=30%, E4>100), "Pass", "Fail") -> Pass | J4: View details | K4: 180 | L4: 0 | M4: =2.059*1000000 -> 2059000 | N4: 0.9737 | O4: 99.95 | P4: =K4/G4 -> 0.058064516 | Q4: =O4*2.5%*(M4*N4) -> 5009614.7 | R4: =Q4/E4 -> 910.83903 | S4: TRUE
A5: Drink AG1 | B5: drinkag1.com | C5: Greens/Multivitamin | D5: US | E5: 360 | F5: 160 | G5: 200 | H5: =G5/E5 -> 0.55555556 | I5: =IF(AND(H5>=50%, E5>100), "Pass", "Fail") -> Pass | K5: 1 | M5: 2.171M | N5: 0.182
A6: Rejuvacare | B6: rejuvacare.com | C6: Health & Wellness | D6: US | E6: 1600 | F6: 790 | G6: 800 | H6: =G6/E6 -> 0.5 | I6: =IF(AND(H6>=30%, E6>100), "Pass", "Fail") -> Pass | J6: View details | K6: 180 | L6: 26 | M6: =1.668*1000000 -> 1668000 | N6: 0.99 | O6: 84.43 | P6: =K6/G6 -> 0.225 | Q6: =O6*2.5%*(M6*N6) -> 3485523.7 | R6: =Q6/E6 -> 2178.4523 | S6: TRUE
A7: Happy Mammoth | B7: happymammoth.com | C7: Wellness | D7: UK | E7: 2500 | F7: 560 | G7: 1900 | H7: =G7/E7 -> 0.76 | I7: =IF(AND(H7>=30%, E7>100), "Pass", "Fail") -> Pass | J7: View details | K7: 172 | L7: 271 | M7: =1.319*1000000 -> 1319000 | N7: 0.8377 | O7: 68.08 | P7: =K7/G7 -> 0.090526316 | Q7: =O7*2.5%*(M7*N7) -> 1880584.6 | R7: =Q7/E7 -> 752.23383 | S7: FALSE | T7: Shopify
A8: Marmens | B8: mengotomars.com | C8: MEN's Health | D8: US | E8: 760 | F8: 450 | G8: 310 | H8: =G8/E8 -> 0.40789474 | I8: =IF(AND(H8>=30%, E8>100), "Pass", "Fail") -> Pass | J8: View details | K8: 68 | L8: 4 | M8: =1.088*1000000 -> 1088000 | N8: 0.753 | O8: 82 | P8: =K8/G8 -> 0.21935484 | Q8: =O8*2.5%*(M8*N8) -> 1679491.2 | R8: =Q8/E8 -> 2209.8568 | S8: FALSE | T8: Shopify
A9: Froya | B9: froyaorganics.com | C9: Women's Wellness | D9: US | E9: 6100 | F9: 1500 | G9: 4600 | H9: =G9/E9 -> 0.75409836 | I9: =IF(AND(H9>=30%, E9>100), "Pass", "Fail") -> Pass | J9: View details | K9: 350 | L9: 68 | M9: 796408 | N9: 0.8985 | O9: 46.08 | P9: =K9/G9 -> 0.076086957 | Q9: =O9*2.5%*(M9*N9) -> 824339.62 | R9: =Q9/E9 -> 135.13764 | S9: FALSE
A10: Nutrafol | B10: nutrafol.com | C10: Hair Health | D10: US | E10: 1500 | F10: 240 | G10: 1200 | H10: =G10/E10 -> 0.8 | I10: =IF(AND(H10>=50%, E10>100), "Pass", "Fail") -> Pass | M10: 2.221M | N10: 0.273
A11: Hone Health | B11: honehealth.com | C11: Men's Health | D11: US | E11: 240 | F11: 170 | G11: 88 | H11: =G11/E11 -> 0.36666667 | I11: =IF(AND(H11>=30%, E11>100), "Pass", "Fail") -> Pass | J11: View details | K11: 0 | L11: 1008 | M11: 789471 | N11: 0.6984 | O11: 179 | P11: =K11/G11 -> 0 | Q11: =O11*2.5%*(M11*N11) -> 2467365.3 | R11: =Q11/E11 -> 10280.689 | S11: FALSE
A12: Ellaola | B12: ellaola.com | C12: Health/Supplement | D12: US | E12: 4400 | F12: 2700 | G12: 1700 | H12: =G12/E12 -> 0.38636364 | I12: =IF(AND(H12>=30%, E12>100), "Pass", "Fail") -> Pass | J12: View details | K12: 0 | L12: 135 | M12: 699360 | N12: 0.8118 | O12: 92 | P12: =K12/G12 -> 0 | Q12: =O12*2.5%*(M12*N12) -> 1305803 | R12: =Q12/E12 -> 296.77342 | S12: FALSE
A13: Naked Nutrition | B13: nakednutrition.com | C13: Protein/Sports Nutrition | D13: US | E13: 730 | F13: 310 | G13: 420 | H13: =G13/E13 -> 0.57534247 | I13: =IF(AND(H13>=50%, E13>100), "Pass", "Fail") -> Pass | M13: 673291 | N13: 0.1044
A14: Luxeresearchlab | B14: luxeresearchlab.com | C14: Women's Wellness | D14: US | E14: 310 | F14: 170 | G14: 140 | H14: =G14/E14 -> 0.4516129 | I14: =IF(AND(H14>=30%, E14>100), "Pass", "Fail") -> Pass | J14: View details | K14: 74 | L14: 1 | M14: 698267 | N14: 0.932 | O14: 54 | P14: =K14/G14 -> 0.52857143 | Q14: =O14*2.5%*(M14*N14) -> 878559.54 | R14: =Q14/E14 -> 2834.063 | S14: FALSE
A15: Bucked Up | B15: buckedup.com | C15: Sports Nutrition | D15: US | E15: 410 | F15: 150 | G15: 250 | H15: =G15/E15 -> 0.6097561 | I15: =IF(AND(H15>=30%, E15>100), "Pass", "Fail") -> Pass | J15: View details | K15: 0 | L15: 0 | M15: 607745 | N15: 0.8749 | O15: 88 | P15: =K15/G15 -> 0 | Q15: =O15*2.5%*(M15*N15) -> 1169775.4 | R15: =Q15/E15 -> 2853.1108 | S15: FALSE
A16: BulkSupplements | B16: bulksupplements.com | C16: Protein/Sports | D16: US | E16: 190 | F16: 14 | G16: 170 | H16: =G16/E16 -> 0.89473684 | I16: =IF(AND(H16>=50%, E16>100), "Pass", "Fail") -> Pass | M16: 834650 | N16: 0.065
A17: Olavita | B17: try.olavita.co | C17: Women's Wellness | D17: US | E17: 300 | F17: 82 | G17: 210 | H17: =G17/E17 -> 0.7 | I17: =IF(AND(H17>=30%, E17>100), "Pass", "Fail") -> Pass | J17: View details | K17: 60 | L17: 0 | M17: 604931 | N17: 0.9675 | O17: 99.95 | P17: =K17/G17 -> 0.28571429 | Q17: =O17*2.5%*(M17*N17) -> 1462445.3 | R17: =Q17/E17 -> 4874.8176 | S17: TRUE
A18: MuscleFood | B18: musclefood.com | C18: Health/Supplement | D18: UK | E18: 230 | F18: 110 | G18: 110 | H18: =G18/E18 -> 0.47826087 | I18: =IF(AND(H18>=30%, E18>100), "Pass", "Fail") -> Pass | J18: View details | K18: 0 | L18: 53 | M18: 473606 | N18: 0.986 | O18: 62 | P18: =K18/G18 -> 0 | Q18: =O18*2.5%*(M18*N18) -> 723812.05 | R18: =Q18/E18 -> 3147.0089 | S18: FALSE
A19: Alpha Lion | B19: alphalion.com | C19: Sports Nutrition | D19: US | E19: 280 | F19: 160 | G19: 110 | H19: =G19/E19 -> 0.39285714 | I19: =IF(AND(H19>=30%, E19>100), "Pass", "Fail") -> Pass | J19: View details | K19: 7 | L19: 23 | M19: 393544 | N19: 0.863 | O19: 85 | P19: =K19/G19 -> 0.063636364 | Q19: =O19*2.5%*(M19*N19) -> 721710.5 | R19: =Q19/E19 -> 2577.5375 | S19: FALSE
A20: Huel | B20: huel.com | C20: Meal Replacement | D20: US | E20: 810 | F20: 270 | G20: 500 | H20: =G20/E20 -> 0.61728395 | I20: =IF(AND(H20>=50%, E20>100), "Pass", "Fail") -> Pass | M20: 2.106M | N20: 0.258
A21: Primal King | B21: primalviking.com | C21: MEN's Health | D21: US | E21: 840 | F21: 160 | G21: 670 | H21: =G21/E21 -> 0.79761905 | I21: =IF(AND(H21>=30%, E21>100), "Pass", "Fail") -> Pass | J21: View details | K21: 40 | L21: 1 | M21: 361507 | N21: 0.8348 | O21: 84.63 | P21: =K21/G21 -> 0.059701493 | Q21: =O21*2.5%*(M21*N21) -> 638503.82 | R21: =Q21/E21 -> 760.1236 | S21: FALSE
A22: InnoSupps | B22: innosupps.com | C22: Health/Weight Loss | D22: US | E22: 420 | F22: 150 | G22: 270 | H22: =G22/E22 -> 0.64285714 | I22: =IF(AND(H22>=30%, E22>100), "Pass", "Fail") -> Pass | J22: View details | K22: {=XLOOKUP("*" & B22 & "*", Prelander!$B$2:$B$55, Prelander!$D$2:$D$55, "Không tìm thấy", 2)} -> 5 | L22: 41 | M22: 326601 | N22: 1 | O22: 67.08 | P22: =K22/G22 -> 0.018518519 | Q22: =O22*2.5%*(M22*N22) -> 547709.88 | R22: =Q22/E22 -> 1304.0711 | S22: FALSE
A23: Ploise | B23: https://ploise.com | C23: Personal Care | D23: US | E23: 500 | F23: 130 | G23: 280 | H23: =G23/E23 -> 0.56 | I23: =IF(AND(H23>=30%, E23>100), "Pass", "Fail") -> Pass | J23: View details | K23: 97 | L23: 0 | M23: 309389 | N23: 0.9975 | O23: 93.87 | P23: =K23/G23 -> 0.34642857 | Q23: =O23*2.5%*(M23*N23) -> 724243.49 | R23: =Q23/E23 -> 1448.487 | S23: FALSE | T23: NextJs
A24: Equip Foods | B24: equipfoods.com | C24: Beef Protein | D24: US | E24: 750 | F24: 190 | G24: 530 | H24: =G24/E24 -> 0.70666667 | I24: =IF(AND(H24>=30%, E24>100), "Pass", "Fail") -> Pass | J24: View details | K24: 0 | L24: 65 | M24: 283452 | N24: 0.7819 | O24: 98 | P24: =K24/G24 -> 0 | Q24: =O24*2.5%*(M24*N24) -> 542996.24 | R24: =Q24/E24 -> 723.99499 | S24: FALSE
A25: Ancestral Supplements | B25: ancestralsupplements.com | C25: Sports Nutrition | D25: US | E25: 380 | F25: 190 | G25: 180 | H25: =G25/E25 -> 0.47368421 | I25: =IF(AND(H25>=30%, E25>100), "Pass", "Fail") -> Pass | J25: View details | K25: 0 | L25: 216 | M25: 264545 | N25: 0.953 | O25: 92 | P25: =K25/G25 -> 0 | Q25: =O25*2.5%*(M25*N25) -> 579856.19 | R25: =Q25/E25 -> 1525.9373 | S25: FALSE
A26: Myoro | B26: myoro.co | C26: MEN's Health | D26: US | E26: 160 | F26: 78 | G26: 82 | H26: =G26/E26 -> 0.5125 | I26: =IF(AND(H26>=30%, E26>100), "Pass", "Fail") -> Pass | J26: View details | K26: 48 | L26: 1 | M26: 257226 | N26: 0.7411 | O26: 95 | P26: =K26/G26 -> 0.58536585 | Q26: =O26*2.5%*(M26*N26) -> 452746.7 | R26: =Q26/E26 -> 2829.6669 | S26: FALSE
A27: AG1 | B27: drinkag1.com | C27: Greens/Wellness | D27: US | E27: 360 | F27: 160 | G27: 200 | H27: =G27/E27 -> 0.55555556 | I27: =IF(AND(H27>=50%, E27>100), "Pass", "Fail") -> Pass | M27: 2.171M | N27: 0.182
A28: Fiera Cosmetic | B28: fieracosmetics.com | C28: Women's Wellness | D28: US | E28: 150 | F28: 54 | G28: 92 | H28: =G28/E28 -> 0.61333333 | I28: =IF(AND(H28>=30%, E28>100), "Pass", "Fail") -> Pass | J28: View details | K28: 20 | L28: 322 | M28: 243028 | N28: 1 | O28: 78 | P28: =K28/G28 -> 0.2173913 | Q28: =O28*2.5%*(M28*N28) -> 473904.6 | R28: =Q28/E28 -> 3159.364 | S28: FALSE
A29: Orgain | B29: orgain.com | C29: Protein/Organic | D29: US | E29: 190 | F29: 85 | G29: 100 | H29: =G29/E29 -> 0.52631579 | I29: =IF(AND(H29>=50%, E29>100), "Pass", "Fail") -> Pass | M29: 253379 | N29: 0.1952
A30: REDCON1 | B30: redcon1.com | C30: Sports Nutrition | D30: US | E30: 110 | F30: 22 | G30: 80 | H30: =G30/E30 -> 0.72727273 | I30: =IF(AND(H30>=50%, E30>100), "Pass", "Fail") -> Pass | M30: 111321 | N30: 0.2304
A31: Pendulum | B31: pendulumlife.com | C31: Gut Health/Probiotics | D31: US | E31: 210 | F31: 110 | G31: 76 | H31: =G31/E31 -> 0.36190476 | I31: =IF(AND(H31>=30%, E31>100), "Pass", "Fail") -> Pass | J31: View details | K31: 0 | L31: 236 | M31: 237589 | N31: 0.842 | O31: 120 | P31: =K31/G31 -> 0 | Q31: =O31*2.5%*(M31*N31) -> 600149.81 | R31: =Q31/E31 -> 2857.8563 | S31: FALSE
A32: The BB Co | B32: thebbco.com | C32: Collagen/Beauty | D32: US | E32: 7600 | F32: 4700 | G32: 2700 | H32: =G32/E32 -> 0.35526316 | I32: =IF(AND(H32>=30%, E32>100), "Pass", "Fail") -> Pass | J32: View details | K32: {=XLOOKUP("*" & B32 & "*", Prelander!$B$2:$B$55, Prelander!$D$2:$D$55, "Không tìm thấy", 2)} -> 221 | L32: 234 | M32: 221871 | N32: 0.9325 | O32: 82 | P32: =K32/G32 -> 0.081851852 | Q32: =O32*2.5%*(M32*N32) -> 424134.15 | R32: =Q32/E32 -> 55.807125 | S32: FALSE
A33: Norse Organics | B33: norseorganics.co | C33: Women's Wellness | D33: US | E33: 910 | F33: 370 | G33: 510 | H33: =G33/E33 -> 0.56043956 | I33: =IF(AND(H33>=30%, E33>100), "Pass", "Fail") -> Pass | J33: View details | K33: 75 | L33: 9 | M33: 163693 | N33: 0.72 | O33: 86 | P33: =K33/G33 -> 0.14705882 | Q33: =O33*2.5%*(M33*N33) -> 253396.76 | R33: =Q33/E33 -> 278.45798 | S33: FALSE
A34: Balmbare | B34: balmbare.com | C34: Women's Wellness | D34: US | E34: 1200 | F34: 220 | G34: 1000 | H34: =G34/E34 -> 0.83333333 | I34: =IF(AND(H34>=30%, E34>100), "Pass", "Fail") -> Pass | J34: View details | K34: 0 | L34: 0 | M34: 163458 | N34: 0.9437 | O34: 55 | P34: =K34/G34 -> 0 | Q34: =O34*2.5%*(M34*N34) -> 212101.06 | R34: =Q34/E34 -> 176.75088 | S34: FALSE
A35: Thorne | B35: thorne.com | C35: Health/Supplements | D35: US | E35: 16000 | F35: 8800 | G35: 6900 | H35: =G35/E35 -> 0.43125 | I35: =IF(AND(H35>=30%, E35>100), "Pass", "Fail") -> Pass | J35: View details | K35: 0 | L35: 0 | M35: =2.065*1000000 -> 2065000 | N35: 0.465 | O35: 95 | P35: =K35/G35 -> 0 | Q35: =O35*2.5%*(M35*N35) -> 2280534.4 | R35: =Q35/E35 -> 142.5334
A36: Truvani | B36: truvani.com | C36: Protein/Wellness | D36: US | E36: 470 | F36: 370 | G36: 250 | H36: =G36/E36 -> 0.53191489 | I36: =IF(AND(H36>=30%, E36>100), "Pass", "Fail") -> Pass | J36: View details | K36: 0 | L36: 0 | M36: 148684 | N36: 0.8547 | O36: 57 | P36: =K36/G36 -> 0 | Q36: =O36*2.5%*(M36*N36) -> 181089.31 | R36: =Q36/E36 -> 385.2964 | S36: FALSE
A37: Naked Nutrition | B37: nakednutrition.com | C37: Protein/Supplements | D37: US | E37: 730 | F37: 310 | G37: 420 | H37: =G37/E37 -> 0.57534247 | I37: =IF(AND(H37>=50%, E37>100), "Pass", "Fail") -> Pass | M37: 673291 | N37: 0.1044
A38: True Protein | B38: trueprotein.com.au | C38: Protein/Supplements | D38: AU | E38: 560 | F38: 250 | G38: 290 | H38: =G38/E38 -> 0.51785714 | I38: =IF(AND(H38>=30%, E38>100), "Pass", "Fail") -> Pass | J38: View details | K38: 5 | L38: 935 | M38: 147912 | N38: 0.6751 | O38: 75 | P38: =K38/G38 -> 0.017241379 | Q38: =O38*2.5%*(M38*N38) -> 187228.86 | R38: =Q38/E38 -> 334.33725 | S38: FALSE
A39: HealthKart | B39: healthkart.com | C39: Supplements/Health | D39: IN | E39: 320 | F39: 210 | G39: 110 | H39: =G39/E39 -> 0.34375 | I39: =IF(AND(H39>=30%, E39>100), "Pass", "Fail") -> Pass | J39: View details | K39: 0 | M39: 1.246M | N39: 0.1802 | O39: 28
A40: Lonvera | B40: lonvera.com | C40: Health/Supplement | D40: US | E40: 1400 | F40: 770 | G40: 600 | H40: =G40/E40 -> 0.42857143 | I40: =IF(AND(H40>=30%, E40>100), "Pass", "Fail") -> Pass | J40: View details | K40: {=XLOOKUP("*" & B40 & "*", Prelander!$B$2:$B$55, Prelander!$D$2:$D$55, "Không tìm thấy", 2)} -> 5 | L40: 1 | M40: 110817 | N40: 1 | O40: 78 | P40: =K40/G40 -> 0.0083333333 | Q40: =O40*2.5%*(M40*N40) -> 216093.15 | R40: =Q40/E40 -> 154.35225 | S40: FALSE
A41: Rejuvia | B41: rejuvia.co | C41: Health & Wellness | D41: US | E41: 540 | F41: 130 | G41: 410 | H41: =G41/E41 -> 0.75925926 | I41: =IF(AND(H41>=30%, E41>100), "Pass", "Fail") -> Pass | J41: View details | K41: {=XLOOKUP("*" & B41 & "*", Prelander!$B$2:$B$55, Prelander!$D$2:$D$55, "Không tìm thấy", 2)} -> 41 | L41: 0 | M41: 99129 | N41: 0.99 | O41: 88 | P41: =K41/G41 -> 0.1 | Q41: =O41*2.5%*(M41*N41) -> 215902.96 | R41: =Q41/E41 -> 399.8203 | S41: FALSE
...

Sheet Prelander
A1: Brand | B1: Prelander url | C1: Ads | D1: Total
A2: The BBCO | B2: https://thebbco.com/pages/ps-radiancy-listicle-dryness-sns | C2: 15 | D2: =SUM(C2:C8) -> 221
B3: https://thebbco.com/pages/radiancy-quiz-flow-2-bof | C3: 1
B4: https://thebbco.com/pages/radiancy-sns-v2 | C4: 1
B5: https://thebbco.com/pages/radiancy-quiz-flow-1 | C5: 9
B6: https://thebbco.com/pages/pp-radiancy-collagen | C6: 104
B7: https://thebbco.com/pages/ps-radiancy-listicle-dryness-pt | C7: 89
B8: https://thebbco.com/pages/pp-provitalize-mttrt2 | C8: 2
A9: Innosupps | B9: https://www.innosupps.com/pages/nitro-wood-magnum-quiz-g | C9: 3 | D9: =SUM(C9:C10) -> 5
B10: https://www.innosupps.com/pages/nitro-wood-magnum-quiz-b | C10: 2
A11: Mivourr | B11: https://mivourr.com/pages/listicle-marriage-back | C11: 1 | D11: =SUM(C11:C17) -> 198
B12: https://mivourr.com/pages/listicle-pain | C12: 1
B13: https://mivourr.com/pages/listicle-tried-everything | C13: 4
B14: https://mivourr.com/pages/listicle-nothing-works | C14: 2
B15: https://mivourr.com/pages/listicle-dryness | C15: 1
B16: https://mivourr.com/pages/listicle | C16: 9
B17: https://thebbco.com/pages/pp-radiancy-collagen | C17: 180
A18: Zenther | B18: https://zenther.co/pages/b085-congruent-listicle | C18: 14 | D18: =SUM(C18:C26) -> 162
B19: https://zenther.co/pages/listicle-ed | C19: 56
B20: https://zenther.co/pages/bp-meds-still-high-numbers | C20: 9
B21: https://zenther.co/pages/dr-who-retired | C21: 2
B22: https://zenther.co/pages/5-reasons-why-cold-extracted-beetroot-could-restore-your-circulation | C22: 1
B23: https://zenther.co/pages/anxiety | C23: 53
B24: https://zenther.co/pages/dropped-40-points-in-3-weeks | C24: 20
B25: https://zenther.co/pages/osbplpa | C25: 3
B26: https://zenther.co/pages/solution-may-be-too-effective | C26: 4
A27: Rejuveen | B27: rejuveen.com/pages/sp-osteva-lumbar | C27: 160 | D27: =SUM(C27:C32) -> 316
B28: https://rejuveen.com/pages/sp-osteva-sns | C28: 4
B29: https://rejuveen.com/pages/anti-rebound-protocol-cpl | C29: 59
B30: https://rejuveen.com/pages/sp-keralush-g | C30: 8
B31: https://rejuveen.com/pages/anti-rebound-protocol-ncpl | C31: 59
B32: https://rejuveen.com/pages/5-ways-glp-1-causes-muscle-wasting | C32: 26
A33: Rejuvia | B33: https://www.rejuvia.co/pages/rejuvia-introduction-listicle | C33: 31 | D33: =SUM(C33:C37) -> 41
B34: https://www.rejuvia.co/pages/veterans | C34: 2
B35: https://www.rejuvia.co/pages/lp2 | C35: 3
B36: https://www.rejuvia.co/pages/lp3 | C36: 3
B37: https://www.rejuvia.co/pages/bogo | C37: 2
A38: Lonvera | B38: https://lonvera.com/pages/vital-bull-lp-1-advertorial | C38: 5 | D38: =SUM(C38) -> 5
A39: Trysaphire | B39: https://trysaphire.com/pages/cl-quiz | C39: 3 | D39: =SUM(C39:C43) -> 56
B40: https://trysaphire.com/pages/bridging-appetite-advertorial-cc-test | C40: 1
...

Sheet Proposal
A1: Quiz | B1: % | C1: Note | D1: Landing | F1: Checkout
A2: https://shop.try-sprtn.com/main-quiz | B2: =193/216 -> 0.89351852 | D2: https://try.cupids.com/products/hypnosis-3 | E2: 1
A3: https://shop.try-forge.com/mens-lifestyle-essentials-1 | B3: =73/250 -> 0.292 | D3: https://secure.try-forge.com/bridge-a1-simple-a1 | E3: =73/273 -> 0.26739927
A4: https://secure.getquietlab.com/sp-m1 | B4: =70/250 -> 0.28 | D4: https://trysculptique.com/pages/top-doctor-i-found-the-real-reason-why-your-foamy-urine-wont-clear | E4: 0.58
A5: https://mengotomars.com/pages/quiz-v6 | B5: 0.124 | D5: https://mengotomars.com/products/30-day-supply-starter-kit | E5: 0.26
A6: Listicle
A7: https://shop.try-forge.com/listicle-eyebags | B7: 0.17
A8: https://mengotomars.com/pages/10-reasons | B8: 0.42
A9: https://www.rejuvia.co/pages/rejuvia-introduction-listicle | B9: 0.6138
A10: Advertorial
A11: https://secure.rejuvacare.com/adv-rc-sm-ig-us-v10-geo | C11: 100% adv
D15: Prelander filter | E15: Traffic filter | G15: Overall
A16: Mars Men | D16: TRUE | E16: https://pro.similarweb.com/?utm_source=addon#/digitalsuite/websiteanalysis/overview/website-performance/*/999/1m?webSource=Total&key=mengotomars.com | F16: TRUE | G16: FALSE
A17: https://mengotomars.com/pages/quiz-v6 | B17: 0.124 | C17: Quiz
A18: https://mengotomars.com/pages/10-reasons | B18: 0.42 | C18: Listicle
A19: https://mengotomars.com/products/30-day-supply-starter-kit | B19: 0.26 | C19: Landing
A22: Forge Men | D22: TRUE | E22: https://pro.similarweb.com/?utm_source=addon#/digitalsuite/websiteanalysis/overview/website-performance/*/999/1m?webSource=Total&key=shop.try-forge.com | F22: TRUE | G22: TRUE
A23: https://shop.try-forge.com/mens-lifestyle-essentials-1 | B23: =73/250 -> 0.292 | C23: Quiz
A24: https://shop.try-forge.com/listicle-eyebags | B24: 0.17 | C24: Listicle
A25: https://secure.try-forge.com/bridge-a1-simple-a1 | B25: =73/273 -> 0.26739927 | C25: Landing
A26: https://shop.try-forge.com/quizpage
A27: https://shop.try-forge.com/listicles-sales-page
D28: FALSE | F28: FALSE | G28: FALSE
A29: Rejuvacare | D29: FALSE | F29: FALSE | G29: FALSE
A30: https://secure.rejuvacare.com/adv-rc-sm-ig-us-v10-geo | B30: 1 | C30: VSL + Advertorial
A32: Tryscultique | D32: FALSE | F32: FALSE | G32: FALSE
A33: https://trysculptique.com/pages/top-doctor-i-found-the-real-reason-why-your-foamy-urine-wont-clear | B33: 0.58 | C33: VSL + ADV + CC's checkout

Sheet Scoring Guide
A1: ADSCORE RUBRIC - SCORING GUIDE
A2: AdScore = (Funnel x 0.30) + (Impressions x 0.25) + (Variations x 0.20) + (Creative x 0.15) + (Longevity x 0.10)
A4: Criterion | B4: Score | C4: Description | D4: Weight
A5: Funnel Sophistication | B5: 1 | C5: No clear funnel. Direct link to generic product page | D5: 30%
B6: 2 | C6: Basic product page with minimal optimization
B7: 3 | C7: Decent LP with clear CTA, some social proof
B8: 4 | C8: Optimized funnel with upsells, strong LP, subscription
B9: 5 | C9: Elite: quiz/advertorial, post-purchase flow, retention loop
A11: Est. Impressions/Spend | B11: 1 | C11: Very low activity, few ads, likely small budget | D11: 25%
B12: 2 | C12: Some traction, moderate ad count
B13: 3 | C13: Consistent activity, medium budget signals
B14: 4 | C14: High activity, many active ads, strong spend signals
B15: 5 | C15: Massive scale, very high ad volume, dominant presence
A17: Ad Variations/Iterations | B17: 1 | C17: 1-2 static versions, no testing signal | D17: 20%
B18: 2 | C18: 3-5 versions with minor changes
B19: 3 | C19: 6-10 versions, clear A/B testing
B20: 4 | C20: 11-20 versions, systematic iteration
B21: 5 | C21: 20+ versions, aggressive testing cadence
A23: Creative Quality | B23: 1 | C23: Low quality, stock-looking, weak copy | D23: 15%
B24: 2 | C24: Acceptable but generic design and messaging
B25: 3 | C25: Good design, decent hooks, clear value prop
B26: 4 | C26: Strong design, compelling hooks, strategic copy
B27: 5 | C27: Outstanding: thumb-stopping, pattern-interrupt, elite copy
A29: Ad Longevity | B29: 1 | C29: 30-45 days (minimum threshold) | D29: 10%
B30: 2 | C30: 45-60 days
B31: 3 | C31: 60-90 days
B32: 4 | C32: 90-180 days
B33: 5 | C33: 180+ days (evergreen performer)
A36: DECISION THRESHOLDS
A37: 3.50 - 5.00 | B37: DEEP DIVE | C37: Approved for full funnel research via AntiGravity
A38: 2.50 - 3.49 | B38: WATCH LIST | C38: Monitor for changes, may revisit later
A39: 1.00 - 2.49 | B39: SKIP | C39: Does not meet criteria, filtered out

Sheet Comet Workflow
A1: COMET (PERPLEXITY) WORKFLOW GUIDE
A4: HOW TO USE THIS SYSTEM WITH COMET
A6: STEP 1: Paste the system instruction (ADS_FUNNEL_INTELLIGENCE_SYSTEM_v3_COMET.md) into Comet
A7: STEP 2: Comet will confirm it understands the pipeline and check browser access
A8: STEP 3: Use one of the commands below to start
A10: --- COMMANDS ---
A12: SCOUT (Discovery + Filter + Score):
A13: "Scout D2C supplement brands running image ads on Meta"
A14: "Scout creatine brands in the US market"
A15: "Scout gut health supplement brands"
A17: DEEP DIVE (Full funnel research on approved brand):
A18: "Deep dive ColonBroom"
... A86: Start with Meta Ads Library now. Report what you find as you go.

Sheet Try-Forge ads system
A1: STT | B1: Page | C1: ID | E1: Ad library | F1: Ads count
A2: 1 | B2: https://www.facebook.com/profile.php?id=61582691356528# | C2: Real men Real Story | D2: TRUE | E2: https://www.facebook.com/ads/library/?active_status=active&ad_type=all&country=ALL&is_targeted_country=false&media_type=all&search_type=page&sort_data[mode]=total_impressions&sort_data[direction]=desc&source=page-transparency-widget&view_all_page_id=841202209076612 | F2: 42
A3: 2 | B3: https://www.facebook.com/profile.php?id=61583113801975# | C3: Mens Daily Steals | D3: FALSE | E3: https://www.facebook.com/ads/library/?active_status=active&ad_type=all&country=ALL&is_targeted_country=false&media_type=all&search_type=page&sort_data[mode]=total_impressions&sort_data[direction]=desc&source=page-transparency-widget&view_all_page_id=899263093259951 | F3: 7
A4: 3 | B4: https://www.facebook.com/profile.php?id=61556636866808# | C4: Men's Lifestyle Essentials | D4: TRUE | E4: https://www.facebook.com/ads/library/?active_status=active&ad_type=all&country=ALL&is_targeted_country=false&media_type=all&search_type=page&sort_data[mode]=total_impressions&sort_data[direction]=desc&source=page-transparency-widget&view_all_page_id=197462513459777 | F4: 37
A5: 4 | B5: https://www.facebook.com/profile.php?id=61578850988287# | C5: The Elite Man | D5: TRUE | E5: https://www.facebook.com/ads/library/?active_status=active&ad_type=all&country=ALL&is_targeted_country=false&media_type=all&search_type=page&sort_data[mode]=total_impressions&sort_data[direction]=desc&source=page-transparency-widget&view_all_page_id=781556828366952 | F5: 55
A6: 5 | B6: https://www.facebook.com/profile.php?id=61582904922136# | C6: The Everyday Man | D6: TRUE | E6: https://www.facebook.com/ads/library/?active_status=active&ad_type=all&country=ALL&is_targeted_country=false&media_type=all&search_type=page&sort_data[mode]=total_impressions&sort_data[direction]=desc&source=page-transparency-widget&view_all_page_id=768328883041750 | F6: 34
A7: 6 | B7: https://www.facebook.com/profile.php?id=61583129138493# | C7: Better Performance | D7: TRUE | E7: https://www.facebook.com/ads/library/?active_status=active&ad_type=all&country=ALL&is_targeted_country=false&media_type=all&search_type=page&sort_data[mode]=total_impressions&sort_data[direction]=desc&source=page-transparency-widget&view_all_page_id=892916470563125 | F7: 89
A8: 7 | B8: https://www.facebook.com/profile.php?id=61582935845409# | C8: David Grant | D8: TRUE | E8: https://www.facebook.com/ads/library/?active_status=active&ad_type=all&country=ALL&is_targeted_country=false&media_type=all&search_type=page&sort_data[mode]=total_impressions&sort_data[direction]=desc&source=page-transparency-widget&view_all_page_id=770968199443688 | F8: 18
A9: 8 | B9: https://www.facebook.com/profile.php?id=61560871530927# | C9: Dr. Michael Reed | D9: TRUE | E9: https://www.facebook.com/ads/library/?active_status=active&ad_type=all&country=ALL&is_targeted_country=false&media_type=all&search_type=page&sort_data[mode]=total_impressions&sort_data[direction]=desc&source=page-transparency-widget&view_all_page_id=372402992615401 | F9: 110
A10: 9 | B10: https://www.facebook.com/profile.php?id=61552996366957# | C10: Forge Men | D10: TRUE | E10: https://www.facebook.com/ads/library/?active_status=active&ad_type=all&country=ALL&is_targeted_country=false&media_type=all&search_type=page&sort_data[mode]=total_impressions&sort_data[direction]=desc&source=page-transparency-widget&view_all_page_id=132584606613853 | F10: 60
F11: =sum(F2:F10) -> 452

Sheet try-forge Ads (OLD)
A1: Library ID | B1: Page Name | C1: Start Date | D1: Ad Type | E1: Title | F1: Primary Text | G1: Description | H1: Landing Page | I1: CTA | J1: Media URL | K1: Brand | L1: Facebook Page ID
A2: 843655715426302 | B2: Forge Men | C2: 46098 | D2: Video | E2: ⏰LAST CHANCE!⏰Sale Ends at Midnight... | F2: 🌼BIGGEST Spring Sale EVER!🌼 Get 50% OFF our Beef Tallow Balm, PLUS an EXTRA 20% with code 'SPRING20'! Our Beef Tallow Balm: ✔️Tightens wrinkles QUICKLY ✔️Reduces eye bags and dark spots ✔️Makes your skin thicker, stronger, & hydrated ✔️Helps you go from "tired face" to "sharp & refreshed" Don’t let this one-time deal slip away... an offer this big won’t come back a second time! Tap the button below to get your discount now 👇 | G2: BIGGEST Sale Of The Year! | H2: https://shop.try-forge.com/mens-lifestyle-essentials-1 | I2: Shop now | J2: https://video.fsgn5-3.fna.fbcdn.net/o1/v/t2/f2/m412/AQO24YzBrItZMohpaoG0NucU2KN3jtPLS1xZPDrrjWBgvTWWLyA5e3IEi15x7laWELhAnVO9UVOWdNLn7vpGEogFU0jnan0RkoSsN_HQwA.mp4?_nc_cat=104&_nc_oc=AdoU3NOfMsrKNhcxjp-zTPJULUdn5C9Vxn4mI6Q4MK6xdsYAEqZvLRd-RMw8CREULoQ&_nc_sid=8bf8fe&_nc_ht=video.fsgn5-3.fna.fbcdn.net&_nc_ohc=ltQDEfiXTn0Q7kNvwElwRt3&efg=eyJ2ZW5jb2RlX3RhZyI6Inhwdl9wcm9ncmVzc2l2ZS5WSV9VU0VDQVNFX1BST0RVQ1RfVFlQRS4uQzMuMzYwLnN2ZV9zZCIsInhwdl9hc3NldF9pZCI6MTI3ODYxMzQzNDE0ODk1MCwiYXNzZXRfYWdlX2RheXMiOjIxLCJ2aV91c2VjYXNlX2lkIjoxMDEzOSwiZHVyYXRpb25fcyI6NjQsInVybGdlbl9zb3VyY2UiOiJ3d3cifQ%3D%3D&ccb=17-1&_nc_gid=Bp1XYkM11Sb96VrtMEK0aA&_nc_ss=7a389&_nc_zt=28&oh=00_Af1YbKldRjrETj5BF_T0eG-xn1iS51geSz6o7gwdCHl6Rg&oe=69DAFEC6 | K2: shop.try-forge.com | L2: 132584606613853
A3: 909950778461922 | B3: Forge Men | C3: 46094 | D3: Video | E3: ⏰LAST CHANCE!⏰Sale Ends at Midnight... | F3: 🌼BIGGEST Spring Sale EVER!🌼 Get 50% OFF our Beef Tallow Balm, PLUS an EXTRA 20% with code 'SPRING20'! Our Beef Tallow Balm: ✔️Tightens wrinkles QUICKLY ✔️Reduces eye bags and dark spots ✔️Makes your skin thicker, stronger, & hydrated ✔️Helps you go from "tired face" to "sharp & refreshed" Don’t let this one-time deal slip away... an offer this big won’t come back a second time! Tap the button below to get your discount now 👇 | G3: BIGGEST Sale Of The Year! | H3: https://shop.try-forge.com/mens-lifestyle-essentials-1 | I3: Shop now | J3: https://video.fsgn5-12.fna.fbcdn.net/o1/v/t2/f2/m412/AQOLDxz_ZQ5s2PkMrGeA1jWDf_gTLz5K2kTYT7vgeQYKcAqik5Rz2DsQM8Inp7SAXSbvOHQfbGTKS1wjlFQWbTzpjzjtzerrlfSg6UNJkA.mp4?_nc_cat=103&_nc_oc=AdqSe3RGGGdG0ezLW9Plz8kH5mYbJgTALUKIfFkHLbzB8zKJsLNaPlR0p5RCc_zahPs&_nc_sid=8bf8fe&_nc_ht=video.fsgn5-12.fna.fbcdn.net&_nc_ohc=lCjYy2MCeokQ7kNvwGkJA7d&efg=eyJ2ZW5jb2RlX3RhZyI6Inhwdl9wcm9ncmVzc2l2ZS5WSV9VU0VDQVNFX1BST0RVQ1RfVFlQRS4uQzMuMzYwLnN2ZV9zZCIsInhwdl9hc3NldF9pZCI6MTI3OTk1ODI1NDA4OTc5NSwiYXNzZXRfYWdlX2RheXMiOjI0LCJ2aV91c2VjYXNlX2lkIjoxMDEzOSwiZHVyYXRpb25fcyI6NjYsInVybGdlbl9zb3VyY2UiOiJ3d3cifQ%3D%3D&ccb=17-1&_nc_gid=Bp1XYkM11Sb96VrtMEK0aA&_nc_ss=7a389&_nc_zt=28&oh=00_Af0noGVyaE6ng7ucC6U_w65ku_FWvj1nNAIwtwBVPOgrkg&oe=69DAE3E7 | K3: shop.try-forge.com | L3: 132584606613853
A4: 773401529168938 | B4: Forge Men | C4: 46094 | D4: Image | E4: ⏰LAST CHANCE!⏰Sale Ends at Midnight... | F4: 🌼BIGGEST Spring Sale EVER!🌼 Get 50% OFF our Beef Tallow Balm, PLUS an EXTRA 20% with code 'SPRING20'! Our Beef Tallow Balm: ✔️Tightens wrinkles QUICKLY ✔️Reduces eye bags and dark spots ✔️Makes your skin thicker, stronger, & hydrated ✔️Helps you go from "tired face" to "sharp & refreshed" Don’t let this one-time deal slip away... an offer this big won’t come back a second time! Tap the button below to get your discount now 👇 | G4: BIGGEST Sale Of The Year! | H4: https://shop.try-forge.com/mens-lifestyle-essentials-1 | I4: Shop now | J4: https://scontent.fsgn5-11.fna.fbcdn.net/v/t39.35426-6/651698010_1490025502729327_4252020054043767452_n.jpg?stp=dst-jpg_s600x600_tt6&_nc_cat=110&ccb=1-7&_nc_sid=c53f8f&_nc_ohc=alwwRX-I8K4Q7kNvwFLum-9&_nc_oc=AdqEDX0i_7VZT93zHdIPLcXbpNYKlD7igpH_IIzjzT45KFMhpKErEtiT1CxABIOyGKA&_nc_zt=14&_nc_ht=scontent.fsgn5-11.fna&_nc_gid=Bp1XYkM11Sb96VrtMEK0aA&_nc_ss=7a389&oh=00_Af19QwGwGMWPFVHeqNTcYMafmsetyu_jfo0D7_lAUdtznw&oe=69DB05E9 | K4: shop.try-forge.com | L4: 132584606613853
A5: 2011434282767087 | B5: Forge Men | C5: 46094 | D5: Image | E5: ⏰LAST CHANCE!⏰Sale Ends at Midnight... | F5: 🌼BIGGEST Spring Sale EVER!🌼 Get 50% OFF our Beef Tallow Balm, PLUS an EXTRA 20% with code 'SPRING20'! Our Beef Tallow Balm: ✔️Tightens wrinkles QUICKLY ✔️Reduces eye bags and dark spots ✔️Makes your skin thicker, stronger, & hydrated ✔️Helps you go from "tired face" to "sharp & refreshed" Don’t let this one-time deal slip away... an offer this big won’t come back a second time! Tap the button below to get your discount now 👇 | G5: BIGGEST Sale Of The Year! | H5: https://shop.try-forge.com/mens-lifestyle-essentials-1 | I5: Shop now | J5: https://scontent.fsgn5-3.fna.fbcdn.net/v/t39.35426-6/650237591_2941341806220919_3409998216645146078_n.jpg?stp=dst-jpg_s600x600_tt6&_nc_cat=104&ccb=1-7&_nc_sid=c53f8f&_nc_ohc=Re44RZ-0HPcQ7kNvwGgK9JB&_nc_oc=Adpne6uh3zFwRYpFO8dq4OIRlnLuMmto6K2t1IPrIhQbLgvFuBDB5mngXaS3kbFMjMs&_nc_zt=14&_nc_ht=scontent.fsgn5-3.fna&_nc_gid=Bp1XYkM11Sb96VrtMEK0aA&_nc_ss=7a389&oh=00_Af3NxG6xvv8WffWQZmMTdwWxHXl7GWNIZvlI_hCHtpXDvw&oe=69DAF743 | K5: shop.try-forge.com | L5: 132584606613853
A6: 1837211846969103 | B6: Forge Men | C6: 46099 | D6: Image | E6: ⏰LAST CHANCE!⏰Sale Ends at Midnight... | F6: 🌼BIGGEST Spring Sale EVER!🌼 Get 50% OFF our Beef Tallow Balm, PLUS an EXTRA 20% with code 'SPRING20'! Our Beef Tallow Balm: ✔️Tightens wrinkles QUICKLY ✔️Reduces eye bags and dark spots ✔️Makes your skin thicker, stronger, & hydrated ✔️Helps you go from "tired face" to "sharp & refreshed" Don’t let this one-time deal slip away... an offer this big won’t come back a second time! Tap the button below to get your discount now 👇 | G6: BIGGEST Sale Of The Year! | H6: https://shop.try-forge.com/mens-lifestyle-essentials-1 | I6: Shop now | J6: https://scontent.fsgn5-12.fna.fbcdn.net/v/t39.35426-6/651160290_913306771553528_8225281892631199161_n.jpg?stp=dst-jpg_s600x600_tt6&_nc_cat=105&ccb=1-7&_nc_sid=c53f8f&_nc_ohc=dn7_Ra3QzwgQ7kNvwHo2OxU&_nc_oc=Adrz2Cv8r6oQ9jZK9MAN0iSE3S7rWSjdoL8echcFxj5BHh5bujp_xG-_2OmL4j501tA&_nc_zt=14&_nc_ht=scontent.fsgn5-12.fna&_nc_gid=Bp1XYkM11Sb96VrtMEK0aA&_nc_ss=7a389&oh=00_Af3cTYzCOywpGNZ4H8kkB58zXbt2ceLOzbJefTZRyQ9pRg&oe=69DAE18D | K6: shop.try-forge.com | L6: 132584606613853
A7: 2130137494484715 | B7: Forge Men | C7: 46094 | D7: Image | E7: ⏰LAST CHANCE!⏰Sale Ends at Midnight... | F7: BIGGEST Spring Sale EVER! Get 50% OFF our Beef Organ Complex, PLUS an EXTRA 20% with code ‘SPRING20’! Our Beef Organ Complex: ✔️Crushes afternoon energy crashes FAST ✔️Supports healthy testosterone & masculine drive ✔️Sharpens focus and clears brain fog ✔️Helps you go from “dragging through the day” to “firing on all cylinders” Don’t let this one-time deal slip away... an offer this big won’t come back a second time! Tap the button below to get your discount now 👇 | G7: BIGGEST Sale Of The Year! | H7: https://secure.try-forge.com/bridge-a1-simple | I7: Shop now | J7: https://scontent.fsgn5-5.fna.fbcdn.net/v/t39.35426-6/650202832_1425841362282294_1227244675989920267_n.jpg?stp=dst-jpg_s600x600_tt6&_nc_cat=102&ccb=1-7&_nc_sid=c53f8f&_nc_ohc=Om8hYqGnmPsQ7kNvwFUdEz_&_nc_oc=AdoaDg-CRmMieQGsElZiNQ_Qgr6-ctlSdb3Dur28Z9yO_k4hKN32R1fHOuWkA3eDsbM&_nc_zt=14&_nc_ht=scontent.fsgn5-5.fna&_nc_gid=Bp1XYkM11Sb96VrtMEK0aA&_nc_ss=7a389&oh=00_Af3VoVjrst2wicA_6gDEV2iUnT83nY7SdK4-tlcOhYM1fA&oe=69DAFB68 | K7: shop.try-forge.com | L7: 132584606613853
A8: 927980013212752 | B8: Forge Men | C8: 46094 | D8: Image | E8: ⏰LAST CHANCE!⏰Sale Ends at Midnight... | F8: BIGGEST Spring Sale EVER! Get 50% OFF our Beef Organ Complex, PLUS an EXTRA 20% with code ‘SPRING20’! Our Beef Organ Complex: ✔️Crushes afternoon energy crashes FAST ✔️Supports healthy testosterone & masculine drive ✔️Sharpens focus and clears brain fog ✔️Helps you go from “dragging through the day” to “firing on all cylinders” Don’t let this one-time deal slip away... an offer this big won’t come back a second time! Tap the button below to get your discount now 👇 | G8: BIGGEST Sale Of The Year! | H8: https://secure.try-forge.com/bridge-a1-simple | I8: Shop now | J8: https://scontent.fsgn5-3.fna.fbcdn.net/v/t39.35426-6/650247889_925083479928355_2170574637019682351_n.jpg?stp=dst-jpg_s600x600_tt6&_nc_cat=104&ccb=1-7&_nc_sid=c53f8f&_nc_ohc=vDgckAZ0zMoQ7kNvwGQ9dML&_nc_oc=AdpaZ4NCujqS1ZPF4zadFs8zdRcx29TrEHbebURMUFvQCYoZgU0Sr6gLTOpHHs5gEA0&_nc_zt=14&_nc_ht=scontent.fsgn5-3.fna&_nc_gid=Bp1XYkM11Sb96VrtMEK0aA&_nc_ss=7a389&oh=00_Af1Q9tfbSAmQ5G6IEYXKZiXiOYpDfRhpJxa5JOsEhby4_A&oe=69DADBAB | K8: shop.try-forge.com | L8: 132584606613853
A9: 957514440143624 | B9: Forge Men | C9: 46098 | D9: Video | E9: ⏰LAST CHANCE!⏰Sale Ends at Midnight... | F9: 🌼BIGGEST Spring Sale EVER!🌼 Get 50% OFF our Beef Tallow Balm, PLUS an EXTRA 20% with code 'SPRING20'! Our Beef Tallow Balm: ✔️Tightens wrinkles QUICKLY ✔️Reduces eye bags and dark spots ✔️Makes your skin thicker, stronger, & hydrated ✔️Helps you go from "tired face" to "sharp & refreshed" Don’t let this one-time deal slip away... an offer this big won’t come back a second time! Tap the button below to get your discount now 👇 | G9: BIGGEST Sale Of The Year! | H9: https://shop.try-forge.com/mens-lifestyle-essentials-1 | I9: Shop now | J9: https://video.fsgn5-5.fna.fbcdn.net/o1/v/t2/f2/m412/AQPat1MGGFIPLge2kJcJA4OIbSp04p3ePyhK-ePjbMVTtYlF03Bw2OrrX3xcWNDE2vxgi4ohx_pmDjfM4Wf-zhFYjDZsrRGr1OyBtAAaJQ.mp4?_nc_cat=102&_nc_oc=Ado2t4V7NRTf_F2NaDCupeV-hbOr4k76LIBYhcrv6dbYtK7d1GQW36GjyxEUEpaJK4k&_nc_sid=8bf8fe&_nc_ht=video.fsgn5-5.fna.fbcdn.net&_nc_ohc=1LKcSQShl8gQ7kNvwEdqdcn&efg=eyJ2ZW5jb2RlX3RhZyI6Inhwdl9wcm9ncmVzc2l2ZS5WSV9VU0VDQVNFX1BST0RVQ1RfVFlQRS4uQzMuMzYwLnN2ZV9zZCIsInhwdl9hc3NldF9pZCI6MjQ3NDgxODgwMDgyMTMxMjIsImFzc2V0X2FnZV9kYXlzIjoyMSwidmlfdXNlY2FzZV9pZCI6MTAxMzksImR1cmF0aW9uX3MiOjY0LCJ1cmxnZW5fc291cmNlIjoid3d3In0%3D&ccb=17-1&_nc_gid=Bp1XYkM11Sb96VrtMEK0aA&_nc_ss=7a389&_nc_zt=28&oh=00_Af2ZVCgPryfj8NK0GC5D0YWy2njl-WTYv3PlSOtLHOyAhQ&oe=69DB067C | K9: shop.try-forge.com | L9: 132584606613853
A10: 1397620872131162 | B10: Forge Men | C10: 46094 | D10: Video | E10: ⏰LAST CHANCE!⏰Sale Ends at Midnight... | F10: 🌼BIGGEST Spring Sale EVER!🌼 Get 50% OFF our Beef Tallow Balm, PLUS an EXTRA 20% with code 'SPRING20'! Our Beef Tallow Balm: ✔️Tightens wrinkles QUICKLY ✔️Reduces eye bags and dark spots ✔️Makes your skin thicker, stronger, & hydrated ✔️Helps you go from "tired face" to "sharp & refreshed" Don’t let this one-time deal slip away... an offer this big won’t come back a second time! Tap the button below to get your discount now 👇 | G10: BIGGEST Sale Of The Year! | H10: https://shop.try-forge.com/mens-lifestyle-essentials-1 | I10: Shop now | J10: https://video.fsgn5-11.fna.fbcdn.net/o1/v/t2/f2/m412/AQNMHpmkDcDjCZR6C2pl8JlfEvxpsG1-EIn_bLGPVgfTbesGteDZnEGGNzpNBJW33HgAbriMu_fhofIFAYIa-7NhXPGJWdeB3QVdxZdtwg.mp4?_nc_cat=111&_nc_oc=AdoAgK1y6CY1xIAoyqfRA8CbdVB1IU7WkPOnM8BNVBirtVpduKUtUUJ9khGcvZ7XB9Y&_nc_sid=8bf8fe&_nc_ht=video.fsgn5-11.fna.fbcdn.net&_nc_ohc=T98g980kMUgQ7kNvwEfr5Lq&efg=eyJ2ZW5jb2RlX3RhZyI6Inhwdl9wcm9ncmVzc2l2ZS5WSV9VU0VDQVNFX1BST0RVQ1RfVFlQRS4uQzMuMzYwLnN2ZV9zZCIsInhwdl9hc3NldF9pZCI6MjE1OTkxMTA2ODA3ODY5NCwiYXNzZXRfYWdlX2RheXMiOjI0LCJ2aV91c2VjYXNlX2lkIjoxMDEzOSwiZHVyYXRpb25fcyI6NjYsInVybGdlbl9zb3VyY2UiOiJ3d3cifQ%3D%3D&ccb=17-1&_nc_gid=Bp1XYkM11Sb96VrtMEK0aA&_nc_ss=7a389&_nc_zt=28&oh=00_Af00-DcKuVzSV4Vb5j3GiYoPBSTONOrPtNZtECLsvy-Fmg&oe=69DAD52B | K10: shop.try-forge.com | L10: 132584606613853
A11: 905282632379710 | B11: Forge Men | C11: 46094 | D11: Image | E11: ⏰LAST CHANCE!⏰Sale Ends at Midnight... | F11: BIGGEST Spring Sale EVER! Get 50% OFF our Beef Organ Complex, PLUS an EXTRA 20% with code ‘SPRING20’! Our Beef Organ Complex: ✔️Crushes afternoon energy crashes FAST ✔️Supports healthy testosterone & masculine drive ✔️Sharpens focus and clears brain fog ✔️Helps you go from “dragging through the day” to “firing on all cylinders” Don’t let this one-time deal slip away... an offer this big won’t come back a second time! Tap the button below to get your discount now 👇 | G11: BIGGEST Sale Of The Year! | H11: https://secure.try-forge.com/bridge-a1-simple | I11: Shop now | J11: https://scontent.fsgn5-10.fna.fbcdn.net/v/t39.35426-6/650657925_2277926586029021_2430066128123840261_n.jpg?stp=dst-jpg_s600x600_tt6&_nc_cat=106&ccb=1-7&_nc_sid=c53f8f&_nc_ohc=0zVbOY4nTd8Q7kNvwFWxVeX&_nc_oc=AdrrNFguGy84gxGVWExFgk40BysNqz1lc049_s6OKJsAECvyAkD89PF9LL6Vx9jjcKI&_nc_zt=14&_nc_ht=scontent.fsgn5-10.fna&_nc_gid=Bp1XYkM11Sb96VrtMEK0aA&_nc_ss=7a389&oh=00_Af0ABjl00f9O9NSA2N11ZnRA5YOWYwEvG9hIN3n11FuT_g&oe=69DAFF28 | K11: shop.try-forge.com | L11: 132584606613853
A12: 902392829230146 | B12: Forge Men | C12: 46094 | D12: Image | E12: ⏰LAST CHANCE!⏰Sale Ends at Midnight... | F12: BIGGEST Spring Sale EVER! Get 50% OFF our Beef Organ Complex, PLUS an EXTRA 20% with code ‘SPRING20’! Our Beef Organ Complex: ✔️Crushes afternoon energy crashes FAST ✔️Supports healthy testosterone & masculine drive ✔️Sharpens focus and clears brain fog ✔️Helps you go from “dragging through the day” to “firing on all cylinders” Don’t let this one-time deal slip away... an offer this big won’t come back a second time! Tap the button below to get your discount now 👇 | G12: BIGGEST Sale Of The Year! | H12: https://secure.try-forge.com/bridge-a1-simple | I12: Shop now | J12: https://scontent.fsgn5-5.fna.fbcdn.net/v/t39.35426-6/650255937_879864838360202_1793124271261789682_n.jpg?stp=dst-jpg_s600x600_tt6&_nc_cat=108&ccb=1-7&_nc_sid=c53f8f&_nc_ohc=buKSq7RQnRwQ7kNvwHHfuUy&_nc_oc=AdoDvXp7le-izn3v--fvt04ck2oKIbx8VFGDDNAkdx0novc1Zap74SfNrVdmqt0jidM&_nc_zt=14&_nc_ht=scontent.fsgn5-5.fna&_nc_gid=Bp1XYkM11Sb96VrtMEK0aA&_nc_ss=7a389&oh=00_Af0pXA-TGelc8LlNe-pjdvPOQSUq7L8n5j63FEJTqavFdQ&oe=69DAFE77 | K12: shop.try-forge.com | L12: 132584606613853
A13: 1481656907003862 | B13: Forge Men | C13: 46094 | D13: Image | E13: ⏰LAST CHANCE!⏰Sale Ends at Midnight... | F13: BIGGEST Spring Sale EVER! Get 50% OFF our Beef Organ Complex, PLUS an EXTRA 20% with code ‘SPRING20’! Our Beef Organ Complex: ✔️Crushes afternoon energy crashes FAST ✔️Supports healthy testosterone & masculine drive ✔️Sharpens focus and clears brain fog ✔️Helps you go from “dragging through the day” to “firing on all cylinders” Don’t let this one-time deal slip away... an offer this big won’t come back a second time! Tap the button below to get your discount now 👇 | G13: BIGGEST Sale Of The Year! | H13: https://secure.try-forge.com/bridge-a1-simple | I13: Shop now | J13: https://scontent.fsgn5-10.fna.fbcdn.net/v/t39.35426-6/649889788_1699320851449282_2840904895628147779_n.jpg?stp=dst-jpg_s600x600_tt6&_nc_cat=106&ccb=1-7&_nc_sid=c53f8f&_nc_ohc=a6Ok2NLNY0kQ7kNvwE57aYr&_nc_oc=AdpYI1GepwgUEYJyIZyBs081WbF--iBjl4z_WHMpRESgdapspICJ35yDYSqILq4FSJw&_nc_zt=14&_nc_ht=scontent.fsgn5-10.fna&_nc_gid=Bp1XYkM11Sb96VrtMEK0aA&_nc_ss=7a389&oh=00_Af1DR7QUa_teJDgfQuIJvO8Oyi3Z1Z8bxG011cUCowPfVg&oe=69DB09CF | K13: shop.try-forge.com | L13: 132584606613853
A14: 1284198983637393 | B14: Forge Men | C14: 46094 | D14: Image | E14: ⏰LAST CHANCE!⏰Sale Ends at Midnight... | F14: 🌼BIGGEST Spring Sale EVER!🌼 Get 50% OFF our Beef Tallow Balm, PLUS an EXTRA 20% with code 'SPRING20'! Our Beef Tallow Balm: ✔️Tightens wrinkles QUICKLY ✔️Reduces eye bags and dark spots ✔️Makes your skin thicker, stronger, & hydrated ✔️Helps you go from "tired face" to "sharp & refreshed" Don’t let this one-time deal slip away... an offer this big won’t come back a second time! Tap the button below to get your discount now 👇 | G14: BIGGEST Sale Of The Year! | H14: https://shop.try-forge.com/mens-lifestyle-essentials-1 | I14: Shop now | J14: https://scontent.fsgn5-12.fna.fbcdn.net/v/t39.35426-6/650799648_1311126447742807_6393639188288997208_n.jpg?stp=dst-jpg_s600x600_tt6&_nc_cat=105&ccb=1-7&_nc_sid=c53f8f&_nc_ohc=W4VJHuqu9D8Q7kNvwFAnarK&_nc_oc=AdqW2UYMAxSILtfVqjPc9JD4waEjlfycQtxhTZR08SJPYV6BiZY8__JtTYUl0VtpuqE&_nc_zt=14&_nc_ht=scontent.fsgn5-12.fna&_nc_gid=Bp1XYkM11Sb96VrtMEK0aA&_nc_ss=7a389&oh=00_Af3GJdhkP9wNOUtaw4DJCgblEO5U9MPmPzQvKaivwQaP4A&oe=69DAE9EF | K14: shop.try-forge.com | L14: 132584606613853
A15: 945618348165381 | B15: Forge Men | C15: 46099 | D15: Image | E15: ⏰LAST CHANCE!⏰Sale Ends at Midnight... | F15: 🌼BIGGEST Spring Sale EVER!🌼 Get 50% OFF our Beef Tallow Balm, PLUS an EXTRA 20% with code 'SPRING20'! Our Beef Tallow Balm: ✔️Tightens wrinkles QUICKLY ✔️Reduces eye bags and dark spots ✔️Makes your skin thicker, stronger, & hydrated ✔️Helps you go from "tired face" to "sharp & refreshed" Don’t let this one-time deal slip away... an offer this big won’t come back a second time! Tap the button below to get your discount now 👇 | G15: BIGGEST Sale Of The Year! | H15: https://shop.try-forge.com/mens-lifestyle-essentials-1 | I15: Shop now | J15: https://scontent.fsgn5-5.fna.fbcdn.net/v/t39.35426-6/649990795_1627752558575053_3330639560471977331_n.jpg?stp=dst-jpg_s600x600_tt6&_nc_cat=102&ccb=1-7&_nc_sid=c53f8f&_nc_ohc=YxUKKSdm1swQ7kNvwHA278N&_nc_oc=Adrcv8pu3HG0sosA5klZT5d-64EH9Xof5fnQsXW4CD8z11j8eR8X4A8evCgYOX7tpVs&_nc_zt=14&_nc_ht=scontent.fsgn5-5.fna&_nc_gid=Bp1XYkM11Sb96VrtMEK0aA&_nc_ss=7a389&oh=00_Af25d5oPIL0eYQVklBKK8uJkrPpIsLtXI2eAviizWmnA8Q&oe=69DB0388 | K15: shop.try-forge.com | L15: 132584606613853
A16: 948710774475097 | B16: Forge Men | C16: 46113 | D16: Image | E16: ⏰LAST CHANCE!⏰Sale Ends Soon... | F16: 🐰 BIGGEST Easter Sale EVER! 🥚 Get 50% OFF our Beef Tallow Balm, PLUS an EXTRA 20% with code 'EASTER20'! Our Beef Tallow Balm: ✔️Tightens wrinkles QUICKLY ✔️Reduces eye bags and dark spots ✔️Makes your skin thicker, stronger, & hydrated ✔️Helps you go from "tired face" to "sharp & refreshed" Don’t let this one-time deal slip away... an offer this big won’t come back a second time! Tap the button below to get your discount now 👇 | G16: BIGGEST Sale Of The Year! | H16: https://shop.try-forge.com/mens-lifestyle-essentials-1 | I16: Shop now | J16: https://scontent.fsgn5-10.fna.fbcdn.net/v/t39.35426-6/659051336_1626736981980218_8729193912544773036_n.jpg?stp=dst-jpg_s600x600_tt6&_nc_cat=106&ccb=1-7&_nc_sid=c53f8f&_nc_ohc=y-OJsD62w6MQ7kNvwFY_x1H&_nc_oc=AdpHgtOTXyYGnuIfzkedn1gh2sbGjBEzCQ6_rhilDwEzxWTzMsVrtka_eGTKvMJmgkU&_nc_zt=14&_nc_ht=scontent.fsgn5-10.fna&_nc_gid=Bp1XYkM11Sb96VrtMEK0aA&_nc_ss=7a389&oh=00_Af2kg2Up0uT22m3cJgMdkI9fvmDMTT3L6xOfBlvQYwP4GA&oe=69DAF159 | K16: shop.try-forge.com | L16: 132584606613853
A17: 1252746123180726 | B17: Forge Men | C17: 46114 | D17: Video | E17: ⏰LAST CHANCE!⏰Sale Ends Soon... | F17: 🐰 BIGGEST Easter Sale EVER! 🥚 Get 50% OFF our Beef Tallow Balm, PLUS an EXTRA 20% with code 'EASTER20'! Our Beef Tallow Balm: ✔️Tightens wrinkles QUICKLY ✔️Reduces eye bags and dark spots ✔️Makes your skin thicker, stronger, & hydrated ✔️Helps you go from "tired face" to "sharp & refreshed" Don’t let this one-time deal slip away... an offer this big won’t come back a second time! Tap the button below to get your discount now 👇 | G17: BIGGEST Sale Of The Year! | H17: https://shop.try-forge.com/mens-lifestyle-essentials-1 | I17: Shop now | J17: https://video.fsgn5-5.fna.fbcdn.net/o1/v/t2/f2/m412/AQPihg-jfLvQ3NTjy4_xr3vcm5kqoe8XLYv1sYPLf8c1cJm9TbdbpJkVakgPM6r4U4nOADPR4BxFs9ZvErTioein8VcS4pKmjlkMBH7O5A.mp4?_nc_cat=102&_nc_oc=Adq5NYjMThc4LPe0nLrbIseZku-Vnj24mX-vzURjyO0h8zxu3CeU-HN4CbLn-1kIOQg&_nc_sid=8bf8fe&_nc_ht=video.fsgn5-5.fna.fbcdn.net&_nc_ohc=UrFMfKqpLLIQ7kNvwFsJOW1&efg=eyJ2ZW5jb2RlX3RhZyI6Inhwdl9wcm9ncmVzc2l2ZS5WSV9VU0VDQVNFX1BST0RVQ1RfVFlQRS4uQzMuMzYwLnN2ZV9zZCIsInhwdl9hc3NldF9pZCI6ODMzMDYyNDQ5MDg5OTIyLCJhc3NldF9hZ2VfZGF5cyI6NCwidmlfdXNlY2FzZV9pZCI6MTAxMzksImR1cmF0aW9uX3MiOjY3LCJ1cmxnZW5fc291cmNlIjoid3d3In0%3D&ccb=17-1&_nc_gid=Bp1XYkM11Sb96VrtMEK0aA&_nc_ss=7a389&_nc_zt=28&oh=00_Af2XVHDpQjil7cdBHSGWLify0p60wSRiivzSYwh-azRUfg&oe=69DB09B8 | K17: shop.try-forge.com | L17: 132584606613853
A18: 916239317696652 | B18: Forge Men | C18: 46094 | D18: Image | E18: ⏰LAST CHANCE!⏰Sale Ends at Midnight... | F18: BIGGEST Spring Sale EVER! Get 50% OFF our Beef Organ Complex, PLUS an EXTRA 20% with code ‘SPRING20’! Our Beef Organ Complex: ✔️Crushes afternoon energy crashes FAST ✔️Supports healthy testosterone & masculine drive ✔️Sharpens focus and clears brain fog ✔️Helps you go from “dragging through the day” to “firing on all cylinders” Don’t let this one-time deal slip away... an offer this big won’t come back a second time! Tap the button below to get your discount now 👇 | G18: BIGGEST Sale Of The Year! | H18: https://secure.try-forge.com/bridge-a1-simple | I18: Shop now | J18: https://scontent.fsgn5-12.fna.fbcdn.net/v/t39.35426-6/651002120_921382560536549_2502828550064374180_n.jpg?stp=dst-jpg_s600x600_tt6&_nc_cat=105&ccb=1-7&_nc_sid=c53f8f&_nc_ohc=MBOi8Dyr1hsQ7kNvwEhUgtN&_nc_oc=Adrrv3OPweQ9x6NPhZVhWmR0T4DH40A4koBW--NPZne-nEIioYT-r8_RyatUtVcDDpM&_nc_zt=14&_nc_ht=scontent.fsgn5-12.fna&_nc_gid=Bp1XYkM11Sb96VrtMEK0aA&_nc_ss=7a389&oh=00_Af12oo-AsvPHi50n5DGo3BRYvHZ5N5128ePsiSciHdYkdQ&oe=69DADECC | K18: shop.try-forge.com | L18: 132584606613853
A19: 1680981013063841 | B19: Forge Men | C19: 46094 | D19: Image | E19: ⏰LAST CHANCE!⏰Sale Ends at Midnight... | F19: BIGGEST Spring Sale EVER! Get 50% OFF our Beef Organ Complex, PLUS an EXTRA 20% with code ‘SPRING20’! Our Beef Organ Complex: ✔️Crushes afternoon energy crashes FAST ✔️Supports healthy testosterone & masculine drive ✔️Sharpens focus and clears brain fog ✔️Helps you go from “dragging through the day” to “firing on all cylinders” Don’t let this one-time deal slip away... an offer this big won’t come back a second time! Tap the button below to get your discount now 👇 | G19: BIGGEST Sale Of The Year! | H19: https://secure.try-forge.com/bridge-a1-simple | I19: Shop now | J19: https://scontent.fsgn5-3.fna.fbcdn.net/v/t39.35426-6/651727991_1893364691364283_2807277306464139448_n.jpg?stp=dst-jpg_s600x600_tt6&_nc_cat=104&ccb=1-7&_nc_sid=c53f8f&_nc_ohc=YycorbmiXHUQ7kNvwGEqKPk&_nc_oc=AdosoPjILl9YVV4p7TQYtnvmNoCwmJVTRdfq6FsW58DDyLLVqJSqsyayppRGAUcqYSk&_nc_zt=14&_nc_ht=scontent.fsgn5-3.fna&_nc_gid=Bp1XYkM11Sb96VrtMEK0aA&_nc_ss=7a389&oh=00_Af2ALJN6WBfyE1ZGofa8C6AhWhhKMKNRX_iJiGkI9LpOzA&oe=69DAD303 | K19: shop.try-forge.com | L19: 132584606613853
A20: 2176465009781882 | B20: Forge Men | C20: 46115 | D20: Video | E20: ⏰LAST CHANCE!⏰Sale Ends Soon... | F20: 🐰 BIGGEST Easter Sale EVER! 🥚 Get 50% OFF our Beef Tallow Balm, PLUS an EXTRA 20% with code 'EASTER20'! Our Beef Tallow Balm: ✔️Tightens wrinkles QUICKLY ✔️Reduces eye bags and dark spots ✔️Makes your skin thicker, stronger, & hydrated ✔️Helps you go from "tired face" to "sharp & refreshed" Don’t let this one-time deal slip away... an offer this big won’t come back a second time! Tap the button below to get your discount now 👇 | G20: BIGGEST Sale Of The Year! | H20: https://shop.try-forge.com/mens-lifestyle-essentials-1 | I20: Shop now | J20: https://video.fsgn5-10.fna.fbcdn.net/o1/v/t2/f2/m412/AQPyYhVC5sSOTwk_h_H-oKaNDeErPwfOeDSwB7im2gfXB3NmwxqiPqqhs97-SogYD7P-7pU8Zsrudsf6aknEVrVJX9N3ZmtVTzhFRPRvWA.mp4?_nc_cat=101&_nc_oc=AdqqAw1-yw-RqtLOsPCKkUS-fBrbGZDUfsbrmC1XSzJOiCRml0L-ngl_EPLOjKDDkp0&_nc_sid=8bf8fe&_nc_ht=video.fsgn5-10.fna.fbcdn.net&_nc_ohc=XtokDp2joH4Q7kNvwFtKfQ3&efg=eyJ2ZW5jb2RlX3RhZyI6Inhwdl9wcm9ncmVzc2l2ZS5WSV9VU0VDQVNFX1BST0RVQ1RfVFlQRS4uQzMuMzYwLnN2ZV9zZCIsInhwdl9hc3NldF9pZCI6MzQ3NDUyMDc0MjE3NjA3OTksImFzc2V0X2FnZV9kYXlzIjo0LCJ2aV91c2VjYXNlX2lkIjoxMDEzOSwiZHVyYXRpb25fcyI6ODEsInVybGdlbl9zb3VyY2UiOiJ3d3cifQ%3D%3D&ccb=17-1&_nc_gid=Bp1XYkM11Sb96VrtMEK0aA&_nc_ss=7a389&_nc_zt=28&oh=00_Af1p3zk5webgnxglBVbBs1s2n1YSnnjRJ0YJ0ncI6n1kvQ&oe=69DAE4A9 | K20: shop.try-forge.com | L20: 132584606613853
A21: 947524904899748 | B21: Forge Men | C21: 46113 | D21: Image | E21: ⏰LAST CHANCE!⏰Sale Ends Soon... | F21: 🐰 BIGGEST Easter Sale EVER! 🥚 Get 50% OFF our Beef Tallow Balm, PLUS an EXTRA 20% with code 'EASTER20'! Our Beef Tallow Balm: ✔️Tightens wrinkles QUICKLY ✔️Reduces eye bags and dark spots ✔️Makes your skin thicker, stronger, & hydrated ✔️Helps you go from "tired face" to "sharp & refreshed" Don’t let this one-time deal slip away... an offer this big won’t come back a second time! Tap the button below to get your discount now 👇 | G21: BIGGEST Sale Of The Year! | H21: https://shop.try-forge.com/mens-lifestyle-essentials-1 | I21: Shop now | J21: https://scontent.fsgn5-11.fna.fbcdn.net/v/t39.35426-6/658350462_936511149092790_9139663075594128929_n.jpg?stp=dst-jpg_s600x600_tt6&_nc_cat=110&ccb=1-7&_nc_sid=c53f8f&_nc_ohc=xz3G_kUxDeIQ7kNvwFOQRhx&_nc_oc=AdqodAwQ12pBqWXd8REx2NlNg69OMY074LedFIkMqmf3xutl9jNY9lPptGN6Vrfwn4c&_nc_zt=14&_nc_ht=scontent.fsgn5-11.fna&_nc_gid=Bp1XYkM11Sb96VrtMEK0aA&_nc_ss=7a389&oh=00_Af31MKjSIPijCgeGbm3XDOYm5NmNVRIlHRDH-LYPn2hvJQ&oe=69DAD74A | K21: shop.try-forge.com | L21: 132584606613853
A22: 2053124882086804 | B22: Forge Men | C22: 46094 | D22: Video | E22: ⏰LAST CHANCE!⏰Sale Ends at Midnight... | F22: 🌼BIGGEST Spring Sale EVER!🌼 Get 50% OFF our Beef Tallow Balm, PLUS an EXTRA 20% with code 'SPRING20'! Our Beef Tallow Balm: ✔️Tightens wrinkles QUICKLY ✔️Reduces eye bags and dark spots ✔️Makes your skin thicker, stronger, & hydrated ✔️Helps you go from "tired face" to "sharp & refreshed" Don’t let this one-time deal slip away... an offer this big won’t come back a second time! Tap the button below to get your discount now 👇 | G22: BIGGEST Sale Of The Year! | H22: https://shop.try-forge.com/mens-lifestyle-essentials-1 | I22: Shop now | J22: https://video.fsgn5-3.fna.fbcdn.net/o1/v/t2/f2/m412/AQMnHzqx1BM-ixJ3zyMIXsL-nB8WcQnW1TLZEWJ1IwbRFN-g1CCHAkviYj1M8WGPWz91mkSekq9KvJx2VqmNqABrLCgbRbhS-NFvg7GJCg.mp4?_nc_cat=104&_nc_oc=Adr9azCOhO2cSqeYKgA08hc0JCPFzq75YeDem-S-DeAMNssJGoV6z7ulGCnN7eh3-UE&_nc_sid=8bf8fe&_nc_ht=video.fsgn5-3.fna.fbcdn.net&_nc_ohc=6OQ6ncsA2HAQ7kNvwEl-k6m&efg=eyJ2ZW5jb2RlX3RhZyI6Inhwdl9wcm9ncmVzc2l2ZS5WSV9VU0VDQVNFX1BST0RVQ1RfVFlQRS4uQzMuMzYwLnN2ZV9zZCIsInhwdl9hc3NldF9pZCI6MTQ4Nzg1NDA4Mjk0NTQ0MCwiYXNzZXRfYWdlX2RheXMiOjI0LCJ2aV91c2VjYXNlX2lkIjoxMDEzOSwiZHVyYXRpb25fcyI6NjcsInVybGdlbl9zb3VyY2UiOiJ3d3cifQ%3D%3D&ccb=17-1&_nc_gid=Bp1XYkM11Sb96VrtMEK0aA&_nc_ss=7a389&_nc_zt=28&oh=00_Af1aiaa7E98C1JXHpYO6tRL_6jG51R1VhTCXECjyZJYCBA&oe=69DAE346 | K22: shop.try-forge.com | L22: 132584606613853
A23: 3711652668976619 | B23: Forge Men | C23: 46094 | D23: Image | E23: ⏰LAST CHANCE!⏰Sale Ends at Midnight... | F23: BIGGEST Spring Sale EVER! Get 50% OFF our Beef Organ Complex, PLUS an EXTRA 20% with code ‘SPRING20’! Our Beef Organ Complex: ✔️Crushes afternoon energy crashes FAST ✔️Supports healthy testosterone & masculine drive ✔️Sharpens focus and clears brain fog ✔️Helps you go from “dragging through the day” to “firing on all cylinders” Don’t let this one-time deal slip away... an offer this big won’t come back a second time! Tap the button below to get your discount now 👇 | G23: BIGGEST Sale Of The Year! | H23: https://secure.try-forge.com/bridge-a1-simple | I23: Shop now | J23: https://scontent.fsgn5-8.fna.fbcdn.net/v/t39.35426-6/651190181_966175842724266_1564437706204956915_n.jpg?stp=dst-jpg_s600x600_tt6&_nc_cat=109&ccb=1-7&_nc_sid=c53f8f&_nc_ohc=QxZEOZVI128Q7kNvwH2YRzc&_nc_oc=Adrezunt7qGnYE01J7MnGZRTVAXj1BztMDeqxVnOv-xA53uVs1YZnjVNriUNXZBnn5s&_nc_zt=14&_nc_ht=scontent.fsgn5-8.fna&_nc_gid=Bp1XYkM11Sb96VrtMEK0aA&_nc_ss=7a389&oh=00_Af1x_ZwyjHhCzn6LdsRJXtFQsXEMFee688f-tyGEga7Aqw&oe=69DAF090 | K23: shop.try-forge.com | L23: 132584606613853
A24: 913434535005139 | B24: Forge Men | C24: 46098 | D24: Video | E24: ⏰LAST CHANCE!⏰Sale Ends at Midnight... | F24: 🌼BIGGEST Spring Sale EVER!🌼 Get 50% OFF our Beef Tallow Balm, PLUS an EXTRA 20% with code 'SPRING20'! Our Beef Tallow Balm: ✔️Tightens wrinkles QUICKLY ✔️Reduces eye bags and dark spots ✔️Makes your skin thicker, stronger, & hydrated ✔️Helps you go from "tired face" to "sharp & refreshed" Don’t let this one-time deal slip away... an offer this big won’t come back a second time! Tap the button below to get your discount now 👇 | G24: BIGGEST Sale Of The Year! | H24: https://shop.try-forge.com/mens-lifestyle-essentials-1 | I24: Shop now | J24: https://video.fsgn5-12.fna.fbcdn.net/o1/v/t2/f2/m412/AQNnYOHdLZwKZqJ-_AnVd5N7OIYGzn7SzffAfWUPCQcgiHbhXgC1ABoNhmTdGd3s3iMH4yyUXRH1nTcNk0qTEgUSzLowxvaisfKQc9z_zg.mp4?_nc_cat=105&_nc_oc=AdoZzNFmapZG99_MrnSqQqCPx1INeIKlTfNO83CMb8ga3DXi7_3DmINlKEtFn6FAV4A&_nc_sid=8bf8fe&_nc_ht=video.fsgn5-12.fna.fbcdn.net&_nc_ohc=ohoCL4Vbq5sQ7kNvwEr6th9&efg=eyJ2ZW5jb2RlX3RhZyI6Inhwdl9wcm9ncmVzc2l2ZS5WSV9VU0VDQVNFX1BST0RVQ1RfVFlQRS4uQzMuMzYwLnN2ZV9zZCIsInhwdl9hc3NldF9pZCI6MTMxODI5MjMwNjc4ODM4OSwiYXNzZXRfYWdlX2RheXMiOjIxLCJ2aV91c2VjYXNlX2lkIjoxMDEzOSwiZHVyYXRpb25fcyI6NjQsInVybGdlbl9zb3VyY2UiOiJ3d3cifQ%3D%3D&ccb=17-1&_nc_gid=Bp1XYkM11Sb96VrtMEK0aA&_nc_ss=7a389&_nc_zt=28&oh=00_Af3sQQJxFV74WviiqqY_HQPbcCPzyvqCXOxKvqfkDSVhCA&oe=69DAEA9D | K24: shop.try-forge.com | L24: 132584606613853
A25: 2300706067088213 | B25: Forge Men | C25: 46113 | D25: Image | E25: ⏰LAST CHANCE!⏰Sale Ends Soon... | F25: 🐰 BIGGEST Easter Sale EVER! 🥚 Get 50% OFF our Beef Tallow Balm, PLUS an EXTRA 20% with code 'EASTER20'! Our Beef Tallow Balm: ✔️Tightens wrinkles QUICKLY ✔️Reduces eye bags and dark spots ✔️Makes your skin thicker, stronger, & hydrated ✔️Helps you go from "tired face" to "sharp & refreshed" Don’t let this one-time deal slip away... an offer this big won’t come back a second time! Tap the button below to get your discount now 👇 | G25: BIGGEST Sale Of The Year! | H25: https://shop.try-forge.com/mens-lifestyle-essentials-1 | I25: Shop now | J25: https://scontent.fsgn5-3.fna.fbcdn.net/v/t39.35426-6/662096970_2220988795337986_6661381080865781676_n.jpg?stp=dst-jpg_s600x600_tt6&_nc_cat=104&ccb=1-7&_nc_sid=c53f8f&_nc_ohc=XIF8YRHumy8Q7kNvwHYeE3A&_nc_oc=AdokSvuZHTQzpUFF9h_y9BBKaNiNQe8FCdocAB2w0SjcLafG8A8fndNZQvQJO8yM2EQ&_nc_zt=14&_nc_ht=scontent.fsgn5-3.fna&_nc_gid=Bp1XYkM11Sb96VrtMEK0aA&_nc_ss=7a389&oh=00_Af3bWGR_todRFDiYRFQhgQ0qjOABKiFGBlFS9dWh5BwNyA&oe=69DB0A26 | K25: shop.try-forge.com | L25: 132584606613853
A26: 1166126992242272 | B26: Forge Men | C26: 46114 | D26: Video | E26: ⏰LAST CHANCE!⏰Sale Ends Soon... | F26: 🐰 BIGGEST Easter Sale EVER! 🥚 Get 50% OFF our Beef Tallow Balm, PLUS an EXTRA 20% with code 'EASTER20'! Our Beef Tallow Balm: ✔️Tightens wrinkles QUICKLY ✔️Reduces eye bags and dark spots ✔️Makes your skin thicker, stronger, & hydrated ✔️Helps you go from "tired face" to "sharp & refreshed" Don’t let this one-time deal slip away... an offer this big won’t come back a second time! Tap the button below to get your discount now 👇 | G26: BIGGEST Sale Of The Year! | H26: https://shop.try-forge.com/mens-lifestyle-essentials-1 | I26: Shop now | J26: https://video.fsgn5-10.fna.fbcdn.net/o1/v/t2/f2/m412/AQMZWIeWpLHc2kJknSGyrahaAnCYc95wrHsh4Q1bXXYPn_U3kXo3tSCqnwOsSRjz_WAe80GH3wCC9Wec4qsHU2lttit0lsHRllq4fpXJIQ.mp4?_nc_cat=101&_nc_oc=AdoCiHMWFWsTik5oT6vrgnxWVtT0m8p7WSECJ5UbCWBAv6Hti50t7_1Kp9cK6JWQKbo&_nc_sid=8bf8fe&_nc_ht=video.fsgn5-10.fna.fbcdn.net&_nc_ohc=uHrUsMi-ZTQQ7kNvwF2EfNG&efg=eyJ2ZW5jb2RlX3RhZyI6Inhwdl9wcm9ncmVzc2l2ZS5WSV9VU0VDQVNFX1BST0RVQ1RfVFlQRS4uQzMuMzYwLnN2ZV9zZCIsInhwdl9hc3NldF9pZCI6MTg0MDM5MDMwMzMxNjkyMiwiYXNzZXRfYWdlX2RheXMiOjQsInZpX3VzZWNhc2VfaWQiOjEwMTM5LCJkdXJhdGlvbl9zIjoxNTIsInVybGdlbl9zb3VyY2UiOiJ3d3cifQ%3D%3D&ccb=17-1&_nc_gid=Bp1XYkM11Sb96VrtMEK0aA&_nc_ss=7a389&_nc_zt=28&oh=00_Af19JxgbshrkP8ITEoIB5pL7LTdBgpjiN9HgQvw7xxgKXg&oe=69DAED51 | K26: shop.try-forge.com | L26: 132584606613853
A27: 1761288351504493 | B27: Forge Men | C27: 46114 | D27: Video | E27: ⏰LAST CHANCE!⏰Sale Ends Soon... | F27: 🐰 BIGGEST Easter Sale EVER! 🥚 Get 50% OFF our Beef Tallow Balm, PLUS an EXTRA 20% with code 'EASTER20'! Our Beef Tallow Balm: ✔️Tightens wrinkles QUICKLY ✔️Reduces eye bags and dark spots ✔️Makes your skin thicker, stronger, & hydrated ✔️Helps you go from "tired face" to "sharp & refreshed" Don’t let this one-time deal slip away... an offer this big won’t come back a second time! Tap the button below to get your discount now 👇 | G27: BIGGEST Sale Of The Year! | H27: https://shop.try-forge.com/mens-lifestyle-essentials-1 | I27: Shop now | J27: https://video.fsgn5-5.fna.fbcdn.net/o1/v/t2/f2/m412/AQNjoK3LGaJoTEF0ErrA2J6hRvdb1AmRW6lYgiykjQOStAVnU-7ZqGv1xxtL7q2QeMtBi-otA3s0ZRByRPCxFSUSq0sR59O48VZ6La5Rpw.mp4?_nc_cat=108&_nc_oc=AdqXsaetrQntcxEO8SsRfGzu7u-B4vbXymDjvjOlEt_x0moqLsla0FK4SFnfpOvHaiY&_nc_sid=8bf8fe&_nc_ht=video.fsgn5-5.fna.fbcdn.net&_nc_ohc=2fQx_zpBH1wQ7kNvwEWuZZQ&efg=eyJ2ZW5jb2RlX3RhZyI6Inhwdl9wcm9ncmVzc2l2ZS5WSV9VU0VDQVNFX1BST0RVQ1RfVFlQRS4uQzMuMzU2LnN2ZV9zZCIsInhwdl9hc3NldF9pZCI6OTYyODg2OTUyNzUwODk1LCJhc3NldF9hZ2VfZGF5cyI6NCwidmlfdXNlY2FzZV9pZCI6MTAxMzksImR1cmF0aW9uX3MiOjYwLCJ1cmxnZW5fc291cmNlIjoid3d3In0%3D&ccb=17-1&_nc_gid=Bp1XYkM11Sb96VrtMEK0aA&_nc_ss=7a389&_nc_zt=28&oh=00_Af07mVS_fkZyQpRm13wF6nQWgLF5Mhu0hg1y3Y8TAzDkoQ&oe=69DB0312 | K27: shop.try-forge.com | L27: 132584606613853
A28: 1967867417159438 | B28: Forge Men | C28: 46094 | D28: Image | E28: ⏰LAST CHANCE!⏰Sale Ends at Midnight... | F28: BIGGEST Spring Sale EVER! Get 50% OFF our Beef Organ Complex, PLUS an EXTRA 20% with code ‘SPRING20’! Our Beef Organ Complex: ✔️Crushes afternoon energy crashes FAST ✔️Supports healthy testosterone & masculine drive ✔️Sharpens focus and clears brain fog ✔️Helps you go from “dragging through the day” to “firing on all cylinders” Don’t let this one-time deal slip away... an offer this big won’t come back a second time! Tap the button below to get your discount now 👇 | G28: BIGGEST Sale Of The Year! | H28: https://secure.try-forge.com/bridge-a1-simple | I28: Shop now | J28: https://scontent.fsgn5-12.fna.fbcdn.net/v/t39.35426-6/652300469_1640641947113661_2141458782018142170_n.jpg?stp=dst-jpg_s600x600_tt6&_nc_cat=105&ccb=1-7&_nc_sid=c53f8f&_nc_ohc=cOH06Ga7nAYQ7kNvwETRhGs&_nc_oc=AdpnFByDzpJq3dDOidNYP_YhX1y7THILQOiKrvim8hL3FRHu33SYTUIVTAk7RqkNNoI&_nc_zt=14&_nc_ht=scontent.fsgn5-12.fna&_nc_gid=Bp1XYkM11Sb96VrtMEK0aA&_nc_ss=7a389&oh=00_Af0TtwysOhWZiowEsgVtqhweq-Jf3YI3h17fqOntNNv2JA&oe=69DB055B | K28: shop.try-forge.com | L28: 132584606613853
